2019-05-01 17:38:50,325:WARNING:discord.client: PyNaCl is not installed, voice will NOT be supported
2019-05-01 17:38:50,326:INFO:discord.client: logging in using static token
2019-05-01 17:38:50,621:INFO:discord.gateway: Created websocket connected to wss://gateway.discord.gg?encoding=json&v=6&compress=zlib-stream
2019-05-01 17:38:50,623:INFO:discord.gateway: Shard ID None has sent the IDENTIFY payload.
2019-05-01 17:38:50,726:INFO:discord.gateway: Shard ID None has connected to Gateway: gateway-prd-main-njxv, discord-sessions-prd-1-20 (Session ID: 11c1b3486067fdd74dc370973f40881c).
2019-05-01 17:38:52,730:INFO:discord: We have logged in as Jimbo#9428
2019-05-01 17:38:58,312:INFO:discord.client: Cleaning up event loop.
2019-05-01 17:38:58,379:INFO:discord.gateway: Websocket closed with 1000 (), cannot reconnect.
2019-05-01 17:38:58,379:INFO:discord.client: Cleaning up after 2 tasks.
2019-05-01 17:38:59,555:WARNING:discord.client: PyNaCl is not installed, voice will NOT be supported
2019-05-01 17:38:59,556:INFO:discord.client: logging in using static token
2019-05-01 17:38:59,847:INFO:discord.gateway: Created websocket connected to wss://gateway.discord.gg?encoding=json&v=6&compress=zlib-stream
2019-05-01 17:38:59,848:INFO:discord.gateway: Shard ID None has sent the IDENTIFY payload.
2019-05-01 17:38:59,960:INFO:discord.gateway: Shard ID None has connected to Gateway: gateway-prd-main-h2rq, discord-sessions-prd-1-3 (Session ID: cf9cfbc4ac3f4d2aa26697f30e54c2f9).
2019-05-01 17:39:01,964:INFO:discord: We have logged in as Jimbo#9428
2019-05-01 17:39:05,541:INFO:discord.client: Cleaning up event loop.
2019-05-01 17:39:05,612:INFO:discord.gateway: Websocket closed with 1000 (), cannot reconnect.
2019-05-01 17:39:05,612:INFO:discord.client: Cleaning up after 2 tasks.
2019-05-01 17:39:06,568:WARNING:discord.client: PyNaCl is not installed, voice will NOT be supported
2019-05-01 17:39:06,569:INFO:discord.client: logging in using static token
2019-05-01 17:39:06,857:INFO:discord.gateway: Created websocket connected to wss://gateway.discord.gg?encoding=json&v=6&compress=zlib-stream
2019-05-01 17:39:06,861:INFO:discord.gateway: Shard ID None has sent the IDENTIFY payload.
2019-05-01 17:39:07,644:INFO:discord.gateway: Shard ID None has connected to Gateway: gateway-prd-main-hq1t, discord-sessions-prd-1-20 (Session ID: a0e936e40874e9d23627807d427f7c48).
2019-05-01 17:39:09,649:INFO:discord: We have logged in as Jimbo#9428
2019-05-01 17:39:13,242:INFO:discord.client: Cleaning up event loop.
2019-05-01 17:39:13,311:INFO:discord.gateway: Websocket closed with 1000 (), cannot reconnect.
2019-05-01 17:39:13,312:INFO:discord.client: Cleaning up after 2 tasks.
2019-05-01 17:39:13,961:WARNING:discord.client: PyNaCl is not installed, voice will NOT be supported
2019-05-01 17:39:13,961:INFO:discord.client: logging in using static token
2019-05-01 17:39:14,256:INFO:discord.gateway: Created websocket connected to wss://gateway.discord.gg?encoding=json&v=6&compress=zlib-stream
2019-05-01 17:39:14,258:INFO:discord.gateway: Shard ID None has sent the IDENTIFY payload.
2019-05-01 17:39:14,382:INFO:discord.gateway: Shard ID None has connected to Gateway: gateway-prd-main-jg92, discord-sessions-prd-1-9 (Session ID: 986e29647a2cefdd3a27d28cc686421e).
2019-05-01 17:39:16,388:INFO:discord: We have logged in as Jimbo#9428
2019-05-01 17:39:20,388:INFO:discord.client: Cleaning up event loop.
2019-05-01 17:39:20,460:INFO:discord.gateway: Websocket closed with 1000 (), cannot reconnect.
2019-05-01 17:39:20,461:INFO:discord.client: Cleaning up after 2 tasks.
2019-05-01 17:39:31,548:WARNING:discord.client: PyNaCl is not installed, voice will NOT be supported
2019-05-01 17:39:31,549:INFO:discord.client: logging in using static token
2019-05-01 17:39:31,860:INFO:discord.gateway: Created websocket connected to wss://gateway.discord.gg?encoding=json&v=6&compress=zlib-stream
2019-05-01 17:39:31,862:INFO:discord.gateway: Shard ID None has sent the IDENTIFY payload.
2019-05-01 17:39:32,021:INFO:discord.gateway: Shard ID None has connected to Gateway: gateway-prd-main-vv9q, discord-sessions-prd-1-15 (Session ID: cc86541a0bc7aaf4b28a2d939eebd32a).
2019-05-01 17:39:34,025:INFO:discord: We have logged in as Jimbo#9428
2019-05-01 17:39:51,817:INFO:discord.client: Cleaning up event loop.
2019-05-01 17:39:51,885:INFO:discord.gateway: Websocket closed with 1000 (), cannot reconnect.
2019-05-01 17:39:51,886:INFO:discord.client: Cleaning up after 2 tasks.
Task exception was never retrieved
future: <Task finished coro=<_run_event() done, defined at /home/scitronboy/.local/lib/python3.5/site-packages/discord/client.py:253> exception=SystemExit()>
Traceback (most recent call last):
  File "/home/scitronboy/.local/lib/python3.5/site-packages/discord/client.py", line 573, in run
    loop.run_forever()
  File "/usr/lib/python3.5/asyncio/base_events.py", line 421, in run_forever
    self._run_once()
  File "/usr/lib/python3.5/asyncio/base_events.py", line 1424, in _run_once
    handle._run()
  File "/usr/lib/python3.5/asyncio/events.py", line 126, in _run
    self._callback(*self._args)
  File "/usr/lib/python3.5/asyncio/tasks.py", line 315, in _wakeup
    self._step()
  File "/usr/lib/python3.5/asyncio/tasks.py", line 239, in _step
    result = coro.send(None)
  File "/home/scitronboy/.local/lib/python3.5/site-packages/discord/client.py", line 255, in _run_event
    await coro(*args, **kwargs)
  File "/home/scitronboy/.local/lib/python3.5/site-packages/discord/ext/commands/bot.py", line 898, in on_message
    await self.process_commands(message)
  File "/home/scitronboy/.local/lib/python3.5/site-packages/discord/ext/commands/bot.py", line 895, in process_commands
    await self.invoke(ctx)
  File "/home/scitronboy/.local/lib/python3.5/site-packages/discord/ext/commands/bot.py", line 860, in invoke
    await ctx.command.invoke(ctx)
  File "/home/scitronboy/.local/lib/python3.5/site-packages/discord/ext/commands/core.py", line 698, in invoke
    await injected(*ctx.args, **ctx.kwargs)
  File "/home/scitronboy/.local/lib/python3.5/site-packages/discord/ext/commands/core.py", line 63, in wrapped
    ret = await coro(*args, **kwargs)
  File "/home/scitronboy/Jimbo/cogs/util.py", line 14, in die
    sys.exit()
SystemExit
2019-05-01 17:39:59,805:WARNING:discord.client: PyNaCl is not installed, voice will NOT be supported
2019-05-01 17:39:59,806:INFO:discord.client: logging in using static token
2019-05-01 17:40:00,138:INFO:discord.gateway: Created websocket connected to wss://gateway.discord.gg?encoding=json&v=6&compress=zlib-stream
2019-05-01 17:40:00,141:INFO:discord.gateway: Shard ID None has sent the IDENTIFY payload.
2019-05-01 17:40:00,278:INFO:discord.gateway: Shard ID None has connected to Gateway: gateway-prd-main-bnfw, discord-sessions-prd-1-10 (Session ID: ce625d4b8d5f0abd8695a5c64dc060a0).
2019-05-01 17:40:02,283:INFO:discord: We have logged in as Jimbo#9428
2019-05-01 17:40:06,050:INFO:discord.client: Cleaning up event loop.
2019-05-01 17:40:06,346:INFO:discord.gateway: Websocket closed with 1000 (), cannot reconnect.
2019-05-01 17:40:06,346:INFO:discord.client: Cleaning up after 2 tasks.
2019-05-01 17:40:10,052:WARNING:discord.client: PyNaCl is not installed, voice will NOT be supported
2019-05-01 17:40:10,053:INFO:discord.client: logging in using static token
2019-05-01 17:40:10,372:INFO:discord.gateway: Created websocket connected to wss://gateway.discord.gg?encoding=json&v=6&compress=zlib-stream
2019-05-01 17:40:10,374:INFO:discord.gateway: Shard ID None has sent the IDENTIFY payload.
2019-05-01 17:40:10,563:INFO:discord.gateway: Shard ID None has connected to Gateway: gateway-prd-main-x8n3, discord-sessions-prd-1-13 (Session ID: 69df402b3108023d6acafe85a583fc29).
2019-05-01 17:40:12,568:INFO:discord: We have logged in as Jimbo#9428
2019-05-01 17:40:18,134:INFO:discord.client: Cleaning up event loop.
2019-05-01 17:40:18,201:INFO:discord.gateway: Websocket closed with 1000 (), cannot reconnect.
2019-05-01 17:40:18,202:INFO:discord.client: Cleaning up after 2 tasks.
2019-05-01 17:40:23,308:WARNING:discord.client: PyNaCl is not installed, voice will NOT be supported
2019-05-01 17:40:23,309:INFO:discord.client: logging in using static token
2019-05-01 17:40:23,717:INFO:discord.gateway: Created websocket connected to wss://gateway.discord.gg?encoding=json&v=6&compress=zlib-stream
2019-05-01 17:40:23,719:INFO:discord.gateway: Shard ID None has sent the IDENTIFY payload.
2019-05-01 17:40:23,983:INFO:discord.gateway: Shard ID None has connected to Gateway: gateway-prd-main-qb58, discord-sessions-prd-1-8 (Session ID: 86f0f0799e9a05721f8f5db3a96607fd).
2019-05-01 17:40:25,987:INFO:discord: We have logged in as Jimbo#9428
2019-05-01 17:40:33,486:INFO:discord.client: Cleaning up event loop.
2019-05-01 17:40:33,553:INFO:discord.gateway: Websocket closed with 1000 (), cannot reconnect.
2019-05-01 17:40:33,554:INFO:discord.client: Cleaning up after 2 tasks.
2019-05-01 17:40:46,550:WARNING:discord.client: PyNaCl is not installed, voice will NOT be supported
2019-05-01 17:40:46,551:INFO:discord.client: logging in using static token
2019-05-01 17:40:46,851:INFO:discord.gateway: Created websocket connected to wss://gateway.discord.gg?encoding=json&v=6&compress=zlib-stream
2019-05-01 17:40:46,853:INFO:discord.gateway: Shard ID None has sent the IDENTIFY payload.
2019-05-01 17:40:46,955:INFO:discord.gateway: Shard ID None has connected to Gateway: gateway-prd-main-njxv, discord-sessions-prd-1-4 (Session ID: df9b6f5c5e3bcb650938c4372d3651d2).
2019-05-01 17:40:48,959:INFO:discord: We have logged in as Jimbo#9428
2019-05-01 17:41:06,973:WARNING:discord.client: PyNaCl is not installed, voice will NOT be supported
2019-05-01 17:41:06,974:INFO:discord.client: logging in using static token
2019-05-01 17:41:07,307:INFO:discord.gateway: Created websocket connected to wss://gateway.discord.gg?encoding=json&v=6&compress=zlib-stream
2019-05-01 17:41:07,309:INFO:discord.gateway: Shard ID None has sent the IDENTIFY payload.
2019-05-01 17:41:07,407:INFO:discord.gateway: Shard ID None has connected to Gateway: gateway-prd-main-26fh, discord-sessions-prd-1-8 (Session ID: a73a07c60fd940748c836df99534fca5).
2019-05-01 17:41:09,409:INFO:discord: We have logged in as Jimbo#9428
2019-05-01 17:41:16,954:INFO:discord.client: Cleaning up event loop.
Ignoring exception in command help:
Traceback (most recent call last):
  File "/home/scitronboy/.local/lib/python3.5/site-packages/discord/ext/commands/core.py", line 63, in wrapped
    ret = await coro(*args, **kwargs)
  File "/home/scitronboy/.local/lib/python3.5/site-packages/discord/ext/commands/help.py", line 755, in command_callback
    return await self.send_bot_help(mapping)
  File "/home/scitronboy/.local/lib/python3.5/site-packages/discord/ext/commands/help.py", line 959, in send_bot_help
    await self.send_pages()
  File "/home/scitronboy/.local/lib/python3.5/site-packages/discord/ext/commands/help.py", line 894, in send_pages
    await destination.send(page)
  File "/home/scitronboy/.local/lib/python3.5/site-packages/discord/abc.py", line 776, in send
    data = await state.http.send_message(channel.id, content, tts=tts, embed=embed, nonce=nonce)
  File "/home/scitronboy/.local/lib/python3.5/site-packages/discord/http.py", line 158, in request
    async with self.__session.request(method, url, **kwargs) as r:
  File "/home/scitronboy/.local/lib/python3.5/site-packages/aiohttp/client.py", line 1005, in __aenter__
    self._resp = await self._coro
  File "/home/scitronboy/.local/lib/python3.5/site-packages/aiohttp/client.py", line 348, in _request
    raise RuntimeError('Session is closed')
RuntimeError: Session is closed

The above exception was the direct cause of the following exception:

Traceback (most recent call last):
  File "/home/scitronboy/.local/lib/python3.5/site-packages/discord/ext/commands/bot.py", line 860, in invoke
    await ctx.command.invoke(ctx)
  File "/home/scitronboy/.local/lib/python3.5/site-packages/discord/ext/commands/core.py", line 698, in invoke
    await injected(*ctx.args, **ctx.kwargs)
  File "/home/scitronboy/.local/lib/python3.5/site-packages/discord/ext/commands/core.py", line 72, in wrapped
    raise CommandInvokeError(exc) from exc
discord.ext.commands.errors.CommandInvokeError: Command raised an exception: RuntimeError: Session is closed
Ignoring exception in command help:
Traceback (most recent call last):
  File "/home/scitronboy/.local/lib/python3.5/site-packages/discord/ext/commands/core.py", line 63, in wrapped
    ret = await coro(*args, **kwargs)
  File "/home/scitronboy/.local/lib/python3.5/site-packages/discord/ext/commands/help.py", line 755, in command_callback
    return await self.send_bot_help(mapping)
  File "/home/scitronboy/.local/lib/python3.5/site-packages/discord/ext/commands/help.py", line 959, in send_bot_help
    await self.send_pages()
  File "/home/scitronboy/.local/lib/python3.5/site-packages/discord/ext/commands/help.py", line 894, in send_pages
    await destination.send(page)
  File "/home/scitronboy/.local/lib/python3.5/site-packages/discord/abc.py", line 776, in send
    data = await state.http.send_message(channel.id, content, tts=tts, embed=embed, nonce=nonce)
  File "/home/scitronboy/.local/lib/python3.5/site-packages/discord/http.py", line 158, in request
    async with self.__session.request(method, url, **kwargs) as r:
  File "/home/scitronboy/.local/lib/python3.5/site-packages/aiohttp/client.py", line 1005, in __aenter__
    self._resp = await self._coro
  File "/home/scitronboy/.local/lib/python3.5/site-packages/aiohttp/client.py", line 348, in _request
    raise RuntimeError('Session is closed')
RuntimeError: Session is closed

The above exception was the direct cause of the following exception:

Traceback (most recent call last):
  File "/home/scitronboy/.local/lib/python3.5/site-packages/discord/ext/commands/bot.py", line 860, in invoke
    await ctx.command.invoke(ctx)
  File "/home/scitronboy/.local/lib/python3.5/site-packages/discord/ext/commands/core.py", line 698, in invoke
    await injected(*ctx.args, **ctx.kwargs)
  File "/home/scitronboy/.local/lib/python3.5/site-packages/discord/ext/commands/core.py", line 72, in wrapped
    raise CommandInvokeError(exc) from exc
discord.ext.commands.errors.CommandInvokeError: Command raised an exception: RuntimeError: Session is closed
Ignoring exception in command help:
Traceback (most recent call last):
  File "/home/scitronboy/.local/lib/python3.5/site-packages/discord/ext/commands/core.py", line 63, in wrapped
    ret = await coro(*args, **kwargs)
  File "/home/scitronboy/.local/lib/python3.5/site-packages/discord/ext/commands/help.py", line 755, in command_callback
    return await self.send_bot_help(mapping)
  File "/home/scitronboy/.local/lib/python3.5/site-packages/discord/ext/commands/help.py", line 959, in send_bot_help
    await self.send_pages()
  File "/home/scitronboy/.local/lib/python3.5/site-packages/discord/ext/commands/help.py", line 894, in send_pages
    await destination.send(page)
  File "/home/scitronboy/.local/lib/python3.5/site-packages/discord/abc.py", line 776, in send
    data = await state.http.send_message(channel.id, content, tts=tts, embed=embed, nonce=nonce)
  File "/home/scitronboy/.local/lib/python3.5/site-packages/discord/http.py", line 158, in request
    async with self.__session.request(method, url, **kwargs) as r:
  File "/home/scitronboy/.local/lib/python3.5/site-packages/aiohttp/client.py", line 1005, in __aenter__
    self._resp = await self._coro
  File "/home/scitronboy/.local/lib/python3.5/site-packages/aiohttp/client.py", line 348, in _request
    raise RuntimeError('Session is closed')
RuntimeError: Session is closed

The above exception was the direct cause of the following exception:

Traceback (most recent call last):
  File "/home/scitronboy/.local/lib/python3.5/site-packages/discord/ext/commands/bot.py", line 860, in invoke
    await ctx.command.invoke(ctx)
  File "/home/scitronboy/.local/lib/python3.5/site-packages/discord/ext/commands/core.py", line 698, in invoke
    await injected(*ctx.args, **ctx.kwargs)
  File "/home/scitronboy/.local/lib/python3.5/site-packages/discord/ext/commands/core.py", line 72, in wrapped
    raise CommandInvokeError(exc) from exc
discord.ext.commands.errors.CommandInvokeError: Command raised an exception: RuntimeError: Session is closed
Ignoring exception in command help:
Traceback (most recent call last):
  File "/home/scitronboy/.local/lib/python3.5/site-packages/discord/ext/commands/core.py", line 63, in wrapped
    ret = await coro(*args, **kwargs)
  File "/home/scitronboy/.local/lib/python3.5/site-packages/discord/ext/commands/help.py", line 755, in command_callback
    return await self.send_bot_help(mapping)
  File "/home/scitronboy/.local/lib/python3.5/site-packages/discord/ext/commands/help.py", line 959, in send_bot_help
    await self.send_pages()
  File "/home/scitronboy/.local/lib/python3.5/site-packages/discord/ext/commands/help.py", line 894, in send_pages
    await destination.send(page)
  File "/home/scitronboy/.local/lib/python3.5/site-packages/discord/abc.py", line 776, in send
    data = await state.http.send_message(channel.id, content, tts=tts, embed=embed, nonce=nonce)
  File "/home/scitronboy/.local/lib/python3.5/site-packages/discord/http.py", line 158, in request
    async with self.__session.request(method, url, **kwargs) as r:
  File "/home/scitronboy/.local/lib/python3.5/site-packages/aiohttp/client.py", line 1005, in __aenter__
    self._resp = await self._coro
  File "/home/scitronboy/.local/lib/python3.5/site-packages/aiohttp/client.py", line 348, in _request
    raise RuntimeError('Session is closed')
RuntimeError: Session is closed

The above exception was the direct cause of the following exception:

Traceback (most recent call last):
  File "/home/scitronboy/.local/lib/python3.5/site-packages/discord/ext/commands/bot.py", line 860, in invoke
    await ctx.command.invoke(ctx)
  File "/home/scitronboy/.local/lib/python3.5/site-packages/discord/ext/commands/core.py", line 698, in invoke
    await injected(*ctx.args, **ctx.kwargs)
  File "/home/scitronboy/.local/lib/python3.5/site-packages/discord/ext/commands/core.py", line 72, in wrapped
    raise CommandInvokeError(exc) from exc
discord.ext.commands.errors.CommandInvokeError: Command raised an exception: RuntimeError: Session is closed
2019-05-01 17:41:17,032:INFO:discord.gateway: Websocket closed with 1000 (), cannot reconnect.
2019-05-01 17:41:17,032:INFO:discord.client: Cleaning up after 2 tasks.
2019-05-01 17:51:27,335:INFO:discord.client: Cleaning up event loop.
2019-05-01 17:51:27,404:INFO:discord.gateway: Websocket closed with 1000 (), cannot reconnect.
2019-05-01 17:51:27,405:INFO:discord.client: Cleaning up after 2 tasks.
Task exception was never retrieved
future: <Task finished coro=<_run_event() done, defined at /home/scitronboy/.local/lib/python3.5/site-packages/discord/client.py:253> exception=SystemExit()>
Traceback (most recent call last):
  File "/home/scitronboy/.local/lib/python3.5/site-packages/discord/client.py", line 573, in run
    loop.run_forever()
  File "/usr/lib/python3.5/asyncio/base_events.py", line 421, in run_forever
    self._run_once()
  File "/usr/lib/python3.5/asyncio/base_events.py", line 1424, in _run_once
    handle._run()
  File "/usr/lib/python3.5/asyncio/events.py", line 126, in _run
    self._callback(*self._args)
  File "/usr/lib/python3.5/asyncio/tasks.py", line 315, in _wakeup
    self._step()
  File "/usr/lib/python3.5/asyncio/tasks.py", line 239, in _step
    result = coro.send(None)
  File "/home/scitronboy/.local/lib/python3.5/site-packages/discord/client.py", line 255, in _run_event
    await coro(*args, **kwargs)
  File "/home/scitronboy/.local/lib/python3.5/site-packages/discord/ext/commands/bot.py", line 898, in on_message
    await self.process_commands(message)
  File "/home/scitronboy/.local/lib/python3.5/site-packages/discord/ext/commands/bot.py", line 895, in process_commands
    await self.invoke(ctx)
  File "/home/scitronboy/.local/lib/python3.5/site-packages/discord/ext/commands/bot.py", line 860, in invoke
    await ctx.command.invoke(ctx)
  File "/home/scitronboy/.local/lib/python3.5/site-packages/discord/ext/commands/core.py", line 698, in invoke
    await injected(*ctx.args, **ctx.kwargs)
  File "/home/scitronboy/.local/lib/python3.5/site-packages/discord/ext/commands/core.py", line 63, in wrapped
    ret = await coro(*args, **kwargs)
  File "/home/scitronboy/Jimbo/cogs/util.py", line 14, in die
    sys.exit()
SystemExit
2019-05-01 19:46:36,315:WARNING:discord.client: PyNaCl is not installed, voice will NOT be supported
2019-05-01 19:46:36,316:INFO:discord.client: logging in using static token
2019-05-01 19:46:36,596:INFO:discord.gateway: Created websocket connected to wss://gateway.discord.gg?encoding=json&v=6&compress=zlib-stream
2019-05-01 19:46:36,598:INFO:discord.gateway: Shard ID None has sent the IDENTIFY payload.
2019-05-01 19:46:36,860:INFO:discord.gateway: Shard ID None has connected to Gateway: gateway-prd-main-hzjl, discord-sessions-prd-1-2 (Session ID: 4d5dbd201ce011c0ad488b6738b130a5).
2019-05-01 19:46:38,864:INFO:discord: We have logged in as Jimbo#9428
2019-05-01 19:46:39,319:INFO:discord.client: Cleaning up event loop.
2019-05-01 19:46:39,388:INFO:discord.gateway: Websocket closed with 1000 (), cannot reconnect.
2019-05-01 19:46:39,389:INFO:discord.client: Cleaning up after 2 tasks.
2019-05-01 19:48:56,810:WARNING:discord.client: PyNaCl is not installed, voice will NOT be supported
2019-05-01 19:48:56,811:INFO:discord.client: logging in using static token
2019-05-01 19:48:57,096:INFO:discord.gateway: Created websocket connected to wss://gateway.discord.gg?encoding=json&v=6&compress=zlib-stream
2019-05-01 19:48:57,098:INFO:discord.gateway: Shard ID None has sent the IDENTIFY payload.
2019-05-01 19:48:57,213:INFO:discord.gateway: Shard ID None has connected to Gateway: gateway-prd-main-6hd6, discord-sessions-prd-1-6 (Session ID: 21a343eb8229e01adb23b99135541312).
2019-05-01 19:48:59,217:INFO:discord: We have logged in as Jimbo#9428
2019-05-01 19:49:45,836:WARNING:discord.client: PyNaCl is not installed, voice will NOT be supported
2019-05-01 19:49:45,837:INFO:discord.client: logging in using static token
2019-05-01 19:49:46,157:INFO:discord.gateway: Created websocket connected to wss://gateway.discord.gg?encoding=json&v=6&compress=zlib-stream
2019-05-01 19:49:46,159:INFO:discord.gateway: Shard ID None has sent the IDENTIFY payload.
2019-05-01 19:49:46,327:INFO:discord.gateway: Shard ID None has connected to Gateway: gateway-prd-main-6hd6, discord-sessions-prd-1-26 (Session ID: 6326ad44e84ea35d0c737e4d5fab2bc7).
2019-05-01 19:49:48,332:INFO:discord: We have logged in as Jimbo#9428
2019-05-01 19:52:14,092:WARNING:discord.client: PyNaCl is not installed, voice will NOT be supported
2019-05-01 19:52:14,093:INFO:discord.client: logging in using static token
2019-05-01 19:52:14,396:INFO:discord.gateway: Created websocket connected to wss://gateway.discord.gg?encoding=json&v=6&compress=zlib-stream
2019-05-01 19:52:14,398:INFO:discord.gateway: Shard ID None has sent the IDENTIFY payload.
2019-05-01 19:52:15,146:INFO:discord.gateway: Shard ID None has connected to Gateway: gateway-prd-main-9ln1, discord-sessions-prd-1-22 (Session ID: 5d4345132bc07e4dfdfa68e9209e894f).
2019-05-01 19:52:17,150:INFO:discord: We have logged in as Jimbo#9428
Ignoring exception in command restart:
Traceback (most recent call last):
  File "/home/scitronboy/.local/lib/python3.5/site-packages/discord/ext/commands/core.py", line 63, in wrapped
    ret = await coro(*args, **kwargs)
  File "/home/scitronboy/Jimbo/cogs/util.py", line 21, in restart
    await bot.change_presence(status=discord.Status.online, activity=game)
NameError: name 'bot' is not defined

The above exception was the direct cause of the following exception:

Traceback (most recent call last):
  File "/home/scitronboy/.local/lib/python3.5/site-packages/discord/ext/commands/bot.py", line 860, in invoke
    await ctx.command.invoke(ctx)
  File "/home/scitronboy/.local/lib/python3.5/site-packages/discord/ext/commands/core.py", line 698, in invoke
    await injected(*ctx.args, **ctx.kwargs)
  File "/home/scitronboy/.local/lib/python3.5/site-packages/discord/ext/commands/core.py", line 72, in wrapped
    raise CommandInvokeError(exc) from exc
discord.ext.commands.errors.CommandInvokeError: Command raised an exception: NameError: name 'bot' is not defined
Ignoring exception in command restart:
Traceback (most recent call last):
  File "/home/scitronboy/.local/lib/python3.5/site-packages/discord/ext/commands/core.py", line 63, in wrapped
    ret = await coro(*args, **kwargs)
  File "/home/scitronboy/Jimbo/cogs/util.py", line 21, in restart
    await bot.change_presence(status=discord.Status.online, activity=game)
NameError: name 'bot' is not defined

The above exception was the direct cause of the following exception:

Traceback (most recent call last):
  File "/home/scitronboy/.local/lib/python3.5/site-packages/discord/ext/commands/bot.py", line 860, in invoke
    await ctx.command.invoke(ctx)
  File "/home/scitronboy/.local/lib/python3.5/site-packages/discord/ext/commands/core.py", line 698, in invoke
    await injected(*ctx.args, **ctx.kwargs)
  File "/home/scitronboy/.local/lib/python3.5/site-packages/discord/ext/commands/core.py", line 72, in wrapped
    raise CommandInvokeError(exc) from exc
discord.ext.commands.errors.CommandInvokeError: Command raised an exception: NameError: name 'bot' is not defined
Ignoring exception in command restart:
Traceback (most recent call last):
  File "/home/scitronboy/.local/lib/python3.5/site-packages/discord/ext/commands/core.py", line 63, in wrapped
    ret = await coro(*args, **kwargs)
  File "/home/scitronboy/Jimbo/cogs/util.py", line 21, in restart
    await bot.change_presence(status=discord.Status.idle, activity=game)
NameError: name 'bot' is not defined

The above exception was the direct cause of the following exception:

Traceback (most recent call last):
  File "/home/scitronboy/.local/lib/python3.5/site-packages/discord/ext/commands/bot.py", line 860, in invoke
    await ctx.command.invoke(ctx)
  File "/home/scitronboy/.local/lib/python3.5/site-packages/discord/ext/commands/core.py", line 698, in invoke
    await injected(*ctx.args, **ctx.kwargs)
  File "/home/scitronboy/.local/lib/python3.5/site-packages/discord/ext/commands/core.py", line 72, in wrapped
    raise CommandInvokeError(exc) from exc
discord.ext.commands.errors.CommandInvokeError: Command raised an exception: NameError: name 'bot' is not defined
Ignoring exception in command restart:
Traceback (most recent call last):
  File "/home/scitronboy/.local/lib/python3.5/site-packages/discord/ext/commands/core.py", line 63, in wrapped
    ret = await coro(*args, **kwargs)
  File "/home/scitronboy/Jimbo/cogs/util.py", line 21, in restart
    await bot.change_presence(status=discord.Status.idle, activity=game)
NameError: name 'bot' is not defined

The above exception was the direct cause of the following exception:

Traceback (most recent call last):
  File "/home/scitronboy/.local/lib/python3.5/site-packages/discord/ext/commands/bot.py", line 860, in invoke
    await ctx.command.invoke(ctx)
  File "/home/scitronboy/.local/lib/python3.5/site-packages/discord/ext/commands/core.py", line 698, in invoke
    await injected(*ctx.args, **ctx.kwargs)
  File "/home/scitronboy/.local/lib/python3.5/site-packages/discord/ext/commands/core.py", line 72, in wrapped
    raise CommandInvokeError(exc) from exc
discord.ext.commands.errors.CommandInvokeError: Command raised an exception: NameError: name 'bot' is not defined
Ignoring exception in command restart:
Traceback (most recent call last):
  File "/home/scitronboy/.local/lib/python3.5/site-packages/discord/ext/commands/core.py", line 63, in wrapped
    ret = await coro(*args, **kwargs)
  File "/home/scitronboy/Jimbo/cogs/util.py", line 21, in restart
    await bot.change_presence(status=discord.Status.idle, activity=game)
NameError: name 'bot' is not defined

The above exception was the direct cause of the following exception:

Traceback (most recent call last):
  File "/home/scitronboy/.local/lib/python3.5/site-packages/discord/ext/commands/bot.py", line 860, in invoke
    await ctx.command.invoke(ctx)
  File "/home/scitronboy/.local/lib/python3.5/site-packages/discord/ext/commands/core.py", line 698, in invoke
    await injected(*ctx.args, **ctx.kwargs)
  File "/home/scitronboy/.local/lib/python3.5/site-packages/discord/ext/commands/core.py", line 72, in wrapped
    raise CommandInvokeError(exc) from exc
discord.ext.commands.errors.CommandInvokeError: Command raised an exception: NameError: name 'bot' is not defined
Ignoring exception in command restart:
Traceback (most recent call last):
  File "/home/scitronboy/.local/lib/python3.5/site-packages/discord/ext/commands/core.py", line 63, in wrapped
    ret = await coro(*args, **kwargs)
  File "/home/scitronboy/Jimbo/cogs/util.py", line 21, in restart
    await bot.change_presence(status=discord.Status.idle)
NameError: name 'bot' is not defined

The above exception was the direct cause of the following exception:

Traceback (most recent call last):
  File "/home/scitronboy/.local/lib/python3.5/site-packages/discord/ext/commands/bot.py", line 860, in invoke
    await ctx.command.invoke(ctx)
  File "/home/scitronboy/.local/lib/python3.5/site-packages/discord/ext/commands/core.py", line 698, in invoke
    await injected(*ctx.args, **ctx.kwargs)
  File "/home/scitronboy/.local/lib/python3.5/site-packages/discord/ext/commands/core.py", line 72, in wrapped
    raise CommandInvokeError(exc) from exc
discord.ext.commands.errors.CommandInvokeError: Command raised an exception: NameError: name 'bot' is not defined
Ignoring exception in command restart:
Traceback (most recent call last):
  File "/home/scitronboy/.local/lib/python3.5/site-packages/discord/ext/commands/core.py", line 63, in wrapped
    ret = await coro(*args, **kwargs)
  File "/home/scitronboy/Jimbo/cogs/util.py", line 21, in restart
    await bot.change_presence(status=discord.Status.idle)
NameError: name 'bot' is not defined

The above exception was the direct cause of the following exception:

Traceback (most recent call last):
  File "/home/scitronboy/.local/lib/python3.5/site-packages/discord/ext/commands/bot.py", line 860, in invoke
    await ctx.command.invoke(ctx)
  File "/home/scitronboy/.local/lib/python3.5/site-packages/discord/ext/commands/core.py", line 698, in invoke
    await injected(*ctx.args, **ctx.kwargs)
  File "/home/scitronboy/.local/lib/python3.5/site-packages/discord/ext/commands/core.py", line 72, in wrapped
    raise CommandInvokeError(exc) from exc
discord.ext.commands.errors.CommandInvokeError: Command raised an exception: NameError: name 'bot' is not defined
Ignoring exception in command restart:
Traceback (most recent call last):
  File "/home/scitronboy/.local/lib/python3.5/site-packages/discord/ext/commands/core.py", line 63, in wrapped
    ret = await coro(*args, **kwargs)
  File "/home/scitronboy/Jimbo/cogs/util.py", line 21, in restart
    await bot.change_presence(status=discord.Status.idle)
NameError: name 'bot' is not defined

The above exception was the direct cause of the following exception:

Traceback (most recent call last):
  File "/home/scitronboy/.local/lib/python3.5/site-packages/discord/ext/commands/bot.py", line 860, in invoke
    await ctx.command.invoke(ctx)
  File "/home/scitronboy/.local/lib/python3.5/site-packages/discord/ext/commands/core.py", line 698, in invoke
    await injected(*ctx.args, **ctx.kwargs)
  File "/home/scitronboy/.local/lib/python3.5/site-packages/discord/ext/commands/core.py", line 72, in wrapped
    raise CommandInvokeError(exc) from exc
discord.ext.commands.errors.CommandInvokeError: Command raised an exception: NameError: name 'bot' is not defined
Ignoring exception in command restart:
Traceback (most recent call last):
  File "/home/scitronboy/.local/lib/python3.5/site-packages/discord/ext/commands/core.py", line 63, in wrapped
    ret = await coro(*args, **kwargs)
  File "/home/scitronboy/Jimbo/cogs/util.py", line 21, in restart
    await bot.change_presence(status=discord.Status.idle)
NameError: name 'bot' is not defined

The above exception was the direct cause of the following exception:

Traceback (most recent call last):
  File "/home/scitronboy/.local/lib/python3.5/site-packages/discord/ext/commands/bot.py", line 860, in invoke
    await ctx.command.invoke(ctx)
  File "/home/scitronboy/.local/lib/python3.5/site-packages/discord/ext/commands/core.py", line 698, in invoke
    await injected(*ctx.args, **ctx.kwargs)
  File "/home/scitronboy/.local/lib/python3.5/site-packages/discord/ext/commands/core.py", line 72, in wrapped
    raise CommandInvokeError(exc) from exc
discord.ext.commands.errors.CommandInvokeError: Command raised an exception: NameError: name 'bot' is not defined
Ignoring exception in command restart:
Traceback (most recent call last):
  File "/home/scitronboy/.local/lib/python3.5/site-packages/discord/ext/commands/core.py", line 63, in wrapped
    ret = await coro(*args, **kwargs)
  File "/home/scitronboy/Jimbo/cogs/util.py", line 21, in restart
    await bot.change_presence(status=discord.Status.idle)
NameError: name 'bot' is not defined

The above exception was the direct cause of the following exception:

Traceback (most recent call last):
  File "/home/scitronboy/.local/lib/python3.5/site-packages/discord/ext/commands/bot.py", line 860, in invoke
    await ctx.command.invoke(ctx)
  File "/home/scitronboy/.local/lib/python3.5/site-packages/discord/ext/commands/core.py", line 698, in invoke
    await injected(*ctx.args, **ctx.kwargs)
  File "/home/scitronboy/.local/lib/python3.5/site-packages/discord/ext/commands/core.py", line 72, in wrapped
    raise CommandInvokeError(exc) from exc
discord.ext.commands.errors.CommandInvokeError: Command raised an exception: NameError: name 'bot' is not defined
2019-05-01 19:54:25,829:INFO:discord.client: Cleaning up event loop.
2019-05-01 19:54:25,896:INFO:discord.gateway: Websocket closed with 1000 (), cannot reconnect.
2019-05-01 19:54:25,897:INFO:discord.client: Cleaning up after 2 tasks.
Task exception was never retrieved
future: <Task finished coro=<_run_event() done, defined at /home/scitronboy/.local/lib/python3.5/site-packages/discord/client.py:253> exception=SystemExit()>
Traceback (most recent call last):
  File "/home/scitronboy/.local/lib/python3.5/site-packages/discord/client.py", line 573, in run
    loop.run_forever()
  File "/usr/lib/python3.5/asyncio/base_events.py", line 421, in run_forever
    self._run_once()
  File "/usr/lib/python3.5/asyncio/base_events.py", line 1424, in _run_once
    handle._run()
  File "/usr/lib/python3.5/asyncio/events.py", line 126, in _run
    self._callback(*self._args)
  File "/usr/lib/python3.5/asyncio/tasks.py", line 315, in _wakeup
    self._step()
  File "/usr/lib/python3.5/asyncio/tasks.py", line 239, in _step
    result = coro.send(None)
  File "/home/scitronboy/.local/lib/python3.5/site-packages/discord/client.py", line 255, in _run_event
    await coro(*args, **kwargs)
  File "/home/scitronboy/.local/lib/python3.5/site-packages/discord/ext/commands/bot.py", line 898, in on_message
    await self.process_commands(message)
  File "/home/scitronboy/.local/lib/python3.5/site-packages/discord/ext/commands/bot.py", line 895, in process_commands
    await self.invoke(ctx)
  File "/home/scitronboy/.local/lib/python3.5/site-packages/discord/ext/commands/bot.py", line 860, in invoke
    await ctx.command.invoke(ctx)
  File "/home/scitronboy/.local/lib/python3.5/site-packages/discord/ext/commands/core.py", line 698, in invoke
    await injected(*ctx.args, **ctx.kwargs)
  File "/home/scitronboy/.local/lib/python3.5/site-packages/discord/ext/commands/core.py", line 63, in wrapped
    ret = await coro(*args, **kwargs)
  File "/home/scitronboy/Jimbo/cogs/util.py", line 15, in die
    sys.exit()
SystemExit
